{
 "cells": [
  {
   "cell_type": "code",
   "execution_count": 1,
   "metadata": {},
   "outputs": [],
   "source": [
    "import ray\n",
    "import time\n",
    "import pandas as pd"
   ]
  },
  {
   "cell_type": "code",
   "execution_count": 4,
   "metadata": {},
   "outputs": [
    {
     "name": "stderr",
     "output_type": "stream",
     "text": [
      "2019-07-09 13:54:45,322\tINFO node.py:498 -- Process STDOUT and STDERR is being redirected to /tmp/ray/session_2019-07-09_13-54-45_321808_19593/logs.\n",
      "2019-07-09 13:54:45,432\tINFO services.py:409 -- Waiting for redis server at 127.0.0.1:11011 to respond...\n",
      "2019-07-09 13:54:45,547\tINFO services.py:409 -- Waiting for redis server at 127.0.0.1:39112 to respond...\n",
      "2019-07-09 13:54:45,550\tINFO services.py:806 -- Starting Redis shard with 6.87 GB max memory.\n",
      "2019-07-09 13:54:45,563\tINFO node.py:512 -- Process STDOUT and STDERR is being redirected to /tmp/ray/session_2019-07-09_13-54-45_321808_19593/logs.\n",
      "2019-07-09 13:54:45,565\tINFO services.py:1446 -- Starting the Plasma object store with 10.31 GB memory using /tmp.\n",
      "2019-07-09 13:54:48,508\tERROR worker.py:1672 -- Traceback (most recent call last):\n",
      "  File \"/usr/local/lib/python3.7/site-packages/ray/worker.py\", line 930, in _process_task\n",
      "    self._store_outputs_in_object_store(return_object_ids, outputs)\n",
      "  File \"/usr/local/lib/python3.7/site-packages/ray/worker.py\", line 841, in _store_outputs_in_object_store\n",
      "    self.put_object(object_ids[i], outputs[i])\n",
      "  File \"/usr/local/lib/python3.7/site-packages/ray/worker.py\", line 384, in put_object\n",
      "    self.store_and_register(object_id, value)\n",
      "  File \"/usr/local/lib/python3.7/site-packages/ray/worker.py\", line 318, in store_and_register\n",
      "    self.current_job_id))\n",
      "  File \"/usr/local/lib/python3.7/site-packages/ray/worker.py\", line 247, in get_serialization_context\n",
      "    _initialize_serialization(job_id)\n",
      "  File \"/usr/local/lib/python3.7/site-packages/ray/worker.py\", line 1151, in _initialize_serialization\n",
      "    serialization_context = pyarrow.default_serialization_context()\n",
      "  File \"/usr/local/lib/python3.7/site-packages/ray/pyarrow_files/pyarrow/serialization.py\", line 361, in default_serialization_context\n",
      "    register_default_serialization_handlers(context)\n",
      "  File \"/usr/local/lib/python3.7/site-packages/ray/pyarrow_files/pyarrow/serialization.py\", line 356, in register_default_serialization_handlers\n",
      "    _register_custom_pandas_handlers(serialization_context)\n",
      "  File \"/usr/local/lib/python3.7/site-packages/ray/pyarrow_files/pyarrow/serialization.py\", line 150, in _register_custom_pandas_handlers\n",
      "    import pandas as pd\n",
      "  File \"/usr/local/lib/python3.7/site-packages/pandas/__init__.py\", line 23, in <module>\n",
      "    from pandas.compat.numpy import *\n",
      "  File \"/usr/local/lib/python3.7/site-packages/pandas/compat/__init__.py\", line 446, in <module>\n",
      "    import typing\n",
      "  File \"/usr/local/lib/python3.7/site-packages/typing.py\", line 1357, in <module>\n",
      "    class Callable(extra=collections_abc.Callable, metaclass=CallableMeta):\n",
      "  File \"/usr/local/lib/python3.7/site-packages/typing.py\", line 1005, in __new__\n",
      "    self._abc_registry = extra._abc_registry\n",
      "AttributeError: type object 'Callable' has no attribute '_abc_registry'\n",
      "\n",
      "During handling of the above exception, another exception occurred:\n",
      "\n",
      "Traceback (most recent call last):\n",
      "  File \"/usr/local/lib/python3.7/site-packages/ray/workers/default_worker.py\", line 98, in <module>\n",
      "    ray.worker.global_worker.main_loop()\n",
      "  File \"/usr/local/lib/python3.7/site-packages/ray/worker.py\", line 1052, in main_loop\n",
      "    self._wait_for_and_process_task(task)\n",
      "  File \"/usr/local/lib/python3.7/site-packages/ray/worker.py\", line 1003, in _wait_for_and_process_task\n",
      "    self._process_task(task, execution_info)\n",
      "  File \"/usr/local/lib/python3.7/site-packages/ray/worker.py\", line 934, in _process_task\n",
      "    ray.utils.format_error_message(traceback.format_exc()))\n",
      "  File \"/usr/local/lib/python3.7/site-packages/ray/worker.py\", line 943, in _handle_process_task_failure\n",
      "    self._store_outputs_in_object_store(return_object_ids, failure_objects)\n",
      "  File \"/usr/local/lib/python3.7/site-packages/ray/worker.py\", line 841, in _store_outputs_in_object_store\n",
      "    self.put_object(object_ids[i], outputs[i])\n",
      "  File \"/usr/local/lib/python3.7/site-packages/ray/worker.py\", line 384, in put_object\n",
      "    self.store_and_register(object_id, value)\n",
      "  File \"/usr/local/lib/python3.7/site-packages/ray/worker.py\", line 318, in store_and_register\n",
      "    self.current_job_id))\n",
      "  File \"/usr/local/lib/python3.7/site-packages/ray/worker.py\", line 247, in get_serialization_context\n",
      "    _initialize_serialization(job_id)\n",
      "  File \"/usr/local/lib/python3.7/site-packages/ray/worker.py\", line 1151, in _initialize_serialization\n",
      "    serialization_context = pyarrow.default_serialization_context()\n",
      "  File \"/usr/local/lib/python3.7/site-packages/ray/pyarrow_files/pyarrow/serialization.py\", line 361, in default_serialization_context\n",
      "    register_default_serialization_handlers(context)\n",
      "  File \"/usr/local/lib/python3.7/site-packages/ray/pyarrow_files/pyarrow/serialization.py\", line 356, in register_default_serialization_handlers\n",
      "    _register_custom_pandas_handlers(serialization_context)\n",
      "  File \"/usr/local/lib/python3.7/site-packages/ray/pyarrow_files/pyarrow/serialization.py\", line 150, in _register_custom_pandas_handlers\n",
      "    import pandas as pd\n",
      "  File \"/usr/local/lib/python3.7/site-packages/pandas/__init__.py\", line 23, in <module>\n",
      "    from pandas.compat.numpy import *\n",
      "  File \"/usr/local/lib/python3.7/site-packages/pandas/compat/__init__.py\", line 446, in <module>\n",
      "    import typing\n",
      "  File \"/usr/local/lib/python3.7/site-packages/typing.py\", line 1357, in <module>\n",
      "    class Callable(extra=collections_abc.Callable, metaclass=CallableMeta):\n",
      "  File \"/usr/local/lib/python3.7/site-packages/typing.py\", line 1005, in __new__\n",
      "    self._abc_registry = extra._abc_registry\n",
      "AttributeError: type object 'Callable' has no attribute '_abc_registry'\n",
      "\n",
      "  This error is unexpected and should not have happened. Somehow a worker\n",
      "  crashed in an unanticipated way causing the main_loop to throw an exception,\n",
      "  which is being caught in \"python/ray/workers/default_worker.py\".\n",
      "  \n",
      "2019-07-09 13:54:48,510\tERROR worker.py:1672 -- A worker died or was killed while executing task c448b96ba89ae8ad1bd9cebafd48934a.\n",
      "2019-07-09 13:54:48,510\tERROR worker.py:1672 -- Traceback (most recent call last):\n",
      "  File \"/usr/local/lib/python3.7/site-packages/ray/worker.py\", line 930, in _process_task\n",
      "    self._store_outputs_in_object_store(return_object_ids, outputs)\n",
      "  File \"/usr/local/lib/python3.7/site-packages/ray/worker.py\", line 841, in _store_outputs_in_object_store\n",
      "    self.put_object(object_ids[i], outputs[i])\n",
      "  File \"/usr/local/lib/python3.7/site-packages/ray/worker.py\", line 384, in put_object\n",
      "    self.store_and_register(object_id, value)\n",
      "  File \"/usr/local/lib/python3.7/site-packages/ray/worker.py\", line 318, in store_and_register\n",
      "    self.current_job_id))\n",
      "  File \"/usr/local/lib/python3.7/site-packages/ray/worker.py\", line 247, in get_serialization_context\n",
      "    _initialize_serialization(job_id)\n",
      "  File \"/usr/local/lib/python3.7/site-packages/ray/worker.py\", line 1151, in _initialize_serialization\n",
      "    serialization_context = pyarrow.default_serialization_context()\n",
      "  File \"/usr/local/lib/python3.7/site-packages/ray/pyarrow_files/pyarrow/serialization.py\", line 361, in default_serialization_context\n",
      "    register_default_serialization_handlers(context)\n",
      "  File \"/usr/local/lib/python3.7/site-packages/ray/pyarrow_files/pyarrow/serialization.py\", line 356, in register_default_serialization_handlers\n",
      "    _register_custom_pandas_handlers(serialization_context)\n",
      "  File \"/usr/local/lib/python3.7/site-packages/ray/pyarrow_files/pyarrow/serialization.py\", line 150, in _register_custom_pandas_handlers\n",
      "    import pandas as pd\n",
      "  File \"/usr/local/lib/python3.7/site-packages/pandas/__init__.py\", line 23, in <module>\n",
      "    from pandas.compat.numpy import *\n",
      "  File \"/usr/local/lib/python3.7/site-packages/pandas/compat/__init__.py\", line 446, in <module>\n",
      "    import typing\n",
      "  File \"/usr/local/lib/python3.7/site-packages/typing.py\", line 1357, in <module>\n",
      "    class Callable(extra=collections_abc.Callable, metaclass=CallableMeta):\n",
      "  File \"/usr/local/lib/python3.7/site-packages/typing.py\", line 1005, in __new__\n",
      "    self._abc_registry = extra._abc_registry\n",
      "AttributeError: type object 'Callable' has no attribute '_abc_registry'\n",
      "\n",
      "During handling of the above exception, another exception occurred:\n",
      "\n",
      "Traceback (most recent call last):\n",
      "  File \"/usr/local/lib/python3.7/site-packages/ray/workers/default_worker.py\", line 98, in <module>\n",
      "    ray.worker.global_worker.main_loop()\n",
      "  File \"/usr/local/lib/python3.7/site-packages/ray/worker.py\", line 1052, in main_loop\n",
      "    self._wait_for_and_process_task(task)\n",
      "  File \"/usr/local/lib/python3.7/site-packages/ray/worker.py\", line 1003, in _wait_for_and_process_task\n",
      "    self._process_task(task, execution_info)\n",
      "  File \"/usr/local/lib/python3.7/site-packages/ray/worker.py\", line 934, in _process_task\n",
      "    ray.utils.format_error_message(traceback.format_exc()))\n",
      "  File \"/usr/local/lib/python3.7/site-packages/ray/worker.py\", line 943, in _handle_process_task_failure\n",
      "    self._store_outputs_in_object_store(return_object_ids, failure_objects)\n",
      "  File \"/usr/local/lib/python3.7/site-packages/ray/worker.py\", line 841, in _store_outputs_in_object_store\n",
      "    self.put_object(object_ids[i], outputs[i])\n",
      "  File \"/usr/local/lib/python3.7/site-packages/ray/worker.py\", line 384, in put_object\n",
      "    self.store_and_register(object_id, value)\n",
      "  File \"/usr/local/lib/python3.7/site-packages/ray/worker.py\", line 318, in store_and_register\n",
      "    self.current_job_id))\n",
      "  File \"/usr/local/lib/python3.7/site-packages/ray/worker.py\", line 247, in get_serialization_context\n",
      "    _initialize_serialization(job_id)\n",
      "  File \"/usr/local/lib/python3.7/site-packages/ray/worker.py\", line 1151, in _initialize_serialization\n",
      "    serialization_context = pyarrow.default_serialization_context()\n",
      "  File \"/usr/local/lib/python3.7/site-packages/ray/pyarrow_files/pyarrow/serialization.py\", line 361, in default_serialization_context\n",
      "    register_default_serialization_handlers(context)\n",
      "  File \"/usr/local/lib/python3.7/site-packages/ray/pyarrow_files/pyarrow/serialization.py\", line 356, in register_default_serialization_handlers\n",
      "    _register_custom_pandas_handlers(serialization_context)\n",
      "  File \"/usr/local/lib/python3.7/site-packages/ray/pyarrow_files/pyarrow/serialization.py\", line 150, in _register_custom_pandas_handlers\n",
      "    import pandas as pd\n",
      "  File \"/usr/local/lib/python3.7/site-packages/pandas/__init__.py\", line 23, in <module>\n",
      "    from pandas.compat.numpy import *\n",
      "  File \"/usr/local/lib/python3.7/site-packages/pandas/compat/__init__.py\", line 446, in <module>\n",
      "    import typing\n",
      "  File \"/usr/local/lib/python3.7/site-packages/typing.py\", line 1357, in <module>\n",
      "    class Callable(extra=collections_abc.Callable, metaclass=CallableMeta):\n",
      "  File \"/usr/local/lib/python3.7/site-packages/typing.py\", line 1005, in __new__\n",
      "    self._abc_registry = extra._abc_registry\n",
      "AttributeError: type object 'Callable' has no attribute '_abc_registry'\n",
      "\n",
      "  This error is unexpected and should not have happened. Somehow a worker\n",
      "  crashed in an unanticipated way causing the main_loop to throw an exception,\n",
      "  which is being caught in \"python/ray/workers/default_worker.py\".\n",
      "  \n"
     ]
    },
    {
     "name": "stderr",
     "output_type": "stream",
     "text": [
      "2019-07-09 13:54:48,511\tERROR worker.py:1672 -- A worker died or was killed while executing task d7746b90c156318a2f39e762e884df5e.\n",
      "2019-07-09 13:54:48,513\tERROR worker.py:1672 -- Traceback (most recent call last):\n",
      "  File \"/usr/local/lib/python3.7/site-packages/ray/worker.py\", line 930, in _process_task\n",
      "    self._store_outputs_in_object_store(return_object_ids, outputs)\n",
      "  File \"/usr/local/lib/python3.7/site-packages/ray/worker.py\", line 841, in _store_outputs_in_object_store\n",
      "    self.put_object(object_ids[i], outputs[i])\n",
      "  File \"/usr/local/lib/python3.7/site-packages/ray/worker.py\", line 384, in put_object\n",
      "    self.store_and_register(object_id, value)\n",
      "  File \"/usr/local/lib/python3.7/site-packages/ray/worker.py\", line 318, in store_and_register\n",
      "    self.current_job_id))\n",
      "  File \"/usr/local/lib/python3.7/site-packages/ray/worker.py\", line 247, in get_serialization_context\n",
      "    _initialize_serialization(job_id)\n",
      "  File \"/usr/local/lib/python3.7/site-packages/ray/worker.py\", line 1151, in _initialize_serialization\n",
      "    serialization_context = pyarrow.default_serialization_context()\n",
      "  File \"/usr/local/lib/python3.7/site-packages/ray/pyarrow_files/pyarrow/serialization.py\", line 361, in default_serialization_context\n",
      "    register_default_serialization_handlers(context)\n",
      "  File \"/usr/local/lib/python3.7/site-packages/ray/pyarrow_files/pyarrow/serialization.py\", line 356, in register_default_serialization_handlers\n",
      "    _register_custom_pandas_handlers(serialization_context)\n",
      "  File \"/usr/local/lib/python3.7/site-packages/ray/pyarrow_files/pyarrow/serialization.py\", line 150, in _register_custom_pandas_handlers\n",
      "    import pandas as pd\n",
      "  File \"/usr/local/lib/python3.7/site-packages/pandas/__init__.py\", line 23, in <module>\n",
      "    from pandas.compat.numpy import *\n",
      "  File \"/usr/local/lib/python3.7/site-packages/pandas/compat/__init__.py\", line 446, in <module>\n",
      "    import typing\n",
      "  File \"/usr/local/lib/python3.7/site-packages/typing.py\", line 1357, in <module>\n",
      "    class Callable(extra=collections_abc.Callable, metaclass=CallableMeta):\n",
      "  File \"/usr/local/lib/python3.7/site-packages/typing.py\", line 1005, in __new__\n",
      "    self._abc_registry = extra._abc_registry\n",
      "AttributeError: type object 'Callable' has no attribute '_abc_registry'\n",
      "\n",
      "During handling of the above exception, another exception occurred:\n",
      "\n",
      "Traceback (most recent call last):\n",
      "  File \"/usr/local/lib/python3.7/site-packages/ray/workers/default_worker.py\", line 98, in <module>\n",
      "    ray.worker.global_worker.main_loop()\n",
      "  File \"/usr/local/lib/python3.7/site-packages/ray/worker.py\", line 1052, in main_loop\n",
      "    self._wait_for_and_process_task(task)\n",
      "  File \"/usr/local/lib/python3.7/site-packages/ray/worker.py\", line 1003, in _wait_for_and_process_task\n",
      "    self._process_task(task, execution_info)\n",
      "  File \"/usr/local/lib/python3.7/site-packages/ray/worker.py\", line 934, in _process_task\n",
      "    ray.utils.format_error_message(traceback.format_exc()))\n",
      "  File \"/usr/local/lib/python3.7/site-packages/ray/worker.py\", line 943, in _handle_process_task_failure\n",
      "    self._store_outputs_in_object_store(return_object_ids, failure_objects)\n",
      "  File \"/usr/local/lib/python3.7/site-packages/ray/worker.py\", line 841, in _store_outputs_in_object_store\n",
      "    self.put_object(object_ids[i], outputs[i])\n",
      "  File \"/usr/local/lib/python3.7/site-packages/ray/worker.py\", line 384, in put_object\n",
      "    self.store_and_register(object_id, value)\n",
      "  File \"/usr/local/lib/python3.7/site-packages/ray/worker.py\", line 318, in store_and_register\n",
      "    self.current_job_id))\n",
      "  File \"/usr/local/lib/python3.7/site-packages/ray/worker.py\", line 247, in get_serialization_context\n",
      "    _initialize_serialization(job_id)\n",
      "  File \"/usr/local/lib/python3.7/site-packages/ray/worker.py\", line 1151, in _initialize_serialization\n",
      "    serialization_context = pyarrow.default_serialization_context()\n",
      "  File \"/usr/local/lib/python3.7/site-packages/ray/pyarrow_files/pyarrow/serialization.py\", line 361, in default_serialization_context\n",
      "    register_default_serialization_handlers(context)\n",
      "  File \"/usr/local/lib/python3.7/site-packages/ray/pyarrow_files/pyarrow/serialization.py\", line 356, in register_default_serialization_handlers\n",
      "    _register_custom_pandas_handlers(serialization_context)\n",
      "  File \"/usr/local/lib/python3.7/site-packages/ray/pyarrow_files/pyarrow/serialization.py\", line 150, in _register_custom_pandas_handlers\n",
      "    import pandas as pd\n",
      "  File \"/usr/local/lib/python3.7/site-packages/pandas/__init__.py\", line 23, in <module>\n",
      "    from pandas.compat.numpy import *\n",
      "  File \"/usr/local/lib/python3.7/site-packages/pandas/compat/__init__.py\", line 446, in <module>\n",
      "    import typing\n",
      "  File \"/usr/local/lib/python3.7/site-packages/typing.py\", line 1357, in <module>\n",
      "    class Callable(extra=collections_abc.Callable, metaclass=CallableMeta):\n",
      "  File \"/usr/local/lib/python3.7/site-packages/typing.py\", line 1005, in __new__\n",
      "    self._abc_registry = extra._abc_registry\n",
      "AttributeError: type object 'Callable' has no attribute '_abc_registry'\n",
      "\n",
      "  This error is unexpected and should not have happened. Somehow a worker\n",
      "  crashed in an unanticipated way causing the main_loop to throw an exception,\n",
      "  which is being caught in \"python/ray/workers/default_worker.py\".\n",
      "  \n",
      "2019-07-09 13:54:48,514\tERROR worker.py:1672 -- A worker died or was killed while executing task 22aaaa9f27a86f36fb5122ab8a22406b.\n",
      "2019-07-09 13:54:48,538\tERROR worker.py:1672 -- Traceback (most recent call last):\n",
      "  File \"/usr/local/lib/python3.7/site-packages/ray/worker.py\", line 930, in _process_task\n",
      "    self._store_outputs_in_object_store(return_object_ids, outputs)\n",
      "  File \"/usr/local/lib/python3.7/site-packages/ray/worker.py\", line 841, in _store_outputs_in_object_store\n",
      "    self.put_object(object_ids[i], outputs[i])\n",
      "  File \"/usr/local/lib/python3.7/site-packages/ray/worker.py\", line 384, in put_object\n",
      "    self.store_and_register(object_id, value)\n",
      "  File \"/usr/local/lib/python3.7/site-packages/ray/worker.py\", line 318, in store_and_register\n",
      "    self.current_job_id))\n",
      "  File \"/usr/local/lib/python3.7/site-packages/ray/worker.py\", line 247, in get_serialization_context\n",
      "    _initialize_serialization(job_id)\n",
      "  File \"/usr/local/lib/python3.7/site-packages/ray/worker.py\", line 1151, in _initialize_serialization\n",
      "    serialization_context = pyarrow.default_serialization_context()\n",
      "  File \"/usr/local/lib/python3.7/site-packages/ray/pyarrow_files/pyarrow/serialization.py\", line 361, in default_serialization_context\n",
      "    register_default_serialization_handlers(context)\n",
      "  File \"/usr/local/lib/python3.7/site-packages/ray/pyarrow_files/pyarrow/serialization.py\", line 356, in register_default_serialization_handlers\n",
      "    _register_custom_pandas_handlers(serialization_context)\n",
      "  File \"/usr/local/lib/python3.7/site-packages/ray/pyarrow_files/pyarrow/serialization.py\", line 150, in _register_custom_pandas_handlers\n",
      "    import pandas as pd\n",
      "  File \"/usr/local/lib/python3.7/site-packages/pandas/__init__.py\", line 23, in <module>\n",
      "    from pandas.compat.numpy import *\n",
      "  File \"/usr/local/lib/python3.7/site-packages/pandas/compat/__init__.py\", line 446, in <module>\n",
      "    import typing\n",
      "  File \"/usr/local/lib/python3.7/site-packages/typing.py\", line 1357, in <module>\n",
      "    class Callable(extra=collections_abc.Callable, metaclass=CallableMeta):\n",
      "  File \"/usr/local/lib/python3.7/site-packages/typing.py\", line 1005, in __new__\n",
      "    self._abc_registry = extra._abc_registry\n",
      "AttributeError: type object 'Callable' has no attribute '_abc_registry'\n",
      "\n",
      "During handling of the above exception, another exception occurred:\n",
      "\n",
      "Traceback (most recent call last):\n",
      "  File \"/usr/local/lib/python3.7/site-packages/ray/workers/default_worker.py\", line 98, in <module>\n",
      "    ray.worker.global_worker.main_loop()\n",
      "  File \"/usr/local/lib/python3.7/site-packages/ray/worker.py\", line 1052, in main_loop\n",
      "    self._wait_for_and_process_task(task)\n",
      "  File \"/usr/local/lib/python3.7/site-packages/ray/worker.py\", line 1003, in _wait_for_and_process_task\n",
      "    self._process_task(task, execution_info)\n",
      "  File \"/usr/local/lib/python3.7/site-packages/ray/worker.py\", line 934, in _process_task\n",
      "    ray.utils.format_error_message(traceback.format_exc()))\n",
      "  File \"/usr/local/lib/python3.7/site-packages/ray/worker.py\", line 943, in _handle_process_task_failure\n",
      "    self._store_outputs_in_object_store(return_object_ids, failure_objects)\n",
      "  File \"/usr/local/lib/python3.7/site-packages/ray/worker.py\", line 841, in _store_outputs_in_object_store\n",
      "    self.put_object(object_ids[i], outputs[i])\n",
      "  File \"/usr/local/lib/python3.7/site-packages/ray/worker.py\", line 384, in put_object\n",
      "    self.store_and_register(object_id, value)\n",
      "  File \"/usr/local/lib/python3.7/site-packages/ray/worker.py\", line 318, in store_and_register\n",
      "    self.current_job_id))\n",
      "  File \"/usr/local/lib/python3.7/site-packages/ray/worker.py\", line 247, in get_serialization_context\n",
      "    _initialize_serialization(job_id)\n",
      "  File \"/usr/local/lib/python3.7/site-packages/ray/worker.py\", line 1151, in _initialize_serialization\n",
      "    serialization_context = pyarrow.default_serialization_context()\n",
      "  File \"/usr/local/lib/python3.7/site-packages/ray/pyarrow_files/pyarrow/serialization.py\", line 361, in default_serialization_context\n",
      "    register_default_serialization_handlers(context)\n",
      "  File \"/usr/local/lib/python3.7/site-packages/ray/pyarrow_files/pyarrow/serialization.py\", line 356, in register_default_serialization_handlers\n",
      "    _register_custom_pandas_handlers(serialization_context)\n",
      "  File \"/usr/local/lib/python3.7/site-packages/ray/pyarrow_files/pyarrow/serialization.py\", line 150, in _register_custom_pandas_handlers\n",
      "    import pandas as pd\n",
      "  File \"/usr/local/lib/python3.7/site-packages/pandas/__init__.py\", line 23, in <module>\n",
      "    from pandas.compat.numpy import *\n",
      "  File \"/usr/local/lib/python3.7/site-packages/pandas/compat/__init__.py\", line 446, in <module>\n",
      "    import typing\n",
      "  File \"/usr/local/lib/python3.7/site-packages/typing.py\", line 1357, in <module>\n",
      "    class Callable(extra=collections_abc.Callable, metaclass=CallableMeta):\n",
      "  File \"/usr/local/lib/python3.7/site-packages/typing.py\", line 1005, in __new__\n",
      "    self._abc_registry = extra._abc_registry\n",
      "AttributeError: type object 'Callable' has no attribute '_abc_registry'\n",
      "\n",
      "  This error is unexpected and should not have happened. Somehow a worker\n",
      "  crashed in an unanticipated way causing the main_loop to throw an exception,\n",
      "  which is being caught in \"python/ray/workers/default_worker.py\".\n",
      "  \n"
     ]
    },
    {
     "name": "stderr",
     "output_type": "stream",
     "text": [
      "2019-07-09 13:54:48,543\tERROR worker.py:1672 -- A worker died or was killed while executing task 2e86e3e1a10fc8d22af621dd106cfadd.\n"
     ]
    },
    {
     "ename": "RayWorkerError",
     "evalue": "The worker died unexpectedly while executing this task.",
     "output_type": "error",
     "traceback": [
      "\u001b[0;31m---------------------------------------------------------------------------\u001b[0m",
      "\u001b[0;31mRayWorkerError\u001b[0m                            Traceback (most recent call last)",
      "\u001b[0;32m<ipython-input-4-3d3d295bc1e2>\u001b[0m in \u001b[0;36m<module>\u001b[0;34m\u001b[0m\n\u001b[1;32m      5\u001b[0m \u001b[0;34m\u001b[0m\u001b[0m\n\u001b[1;32m      6\u001b[0m \u001b[0mray\u001b[0m\u001b[0;34m.\u001b[0m\u001b[0minit\u001b[0m\u001b[0;34m(\u001b[0m\u001b[0;34m)\u001b[0m\u001b[0;34m\u001b[0m\u001b[0;34m\u001b[0m\u001b[0m\n\u001b[0;32m----> 7\u001b[0;31m \u001b[0mresults\u001b[0m \u001b[0;34m=\u001b[0m \u001b[0mray\u001b[0m\u001b[0;34m.\u001b[0m\u001b[0mget\u001b[0m\u001b[0;34m(\u001b[0m\u001b[0;34m[\u001b[0m\u001b[0mf\u001b[0m\u001b[0;34m.\u001b[0m\u001b[0mremote\u001b[0m\u001b[0;34m(\u001b[0m\u001b[0;34m)\u001b[0m \u001b[0;32mfor\u001b[0m \u001b[0mi\u001b[0m \u001b[0;32min\u001b[0m \u001b[0mrange\u001b[0m\u001b[0;34m(\u001b[0m\u001b[0;36m4\u001b[0m\u001b[0;34m)\u001b[0m\u001b[0;34m]\u001b[0m\u001b[0;34m)\u001b[0m\u001b[0;34m\u001b[0m\u001b[0;34m\u001b[0m\u001b[0m\n\u001b[0m\u001b[1;32m      8\u001b[0m \u001b[0mray\u001b[0m\u001b[0;34m.\u001b[0m\u001b[0mshutdown\u001b[0m\u001b[0;34m(\u001b[0m\u001b[0;34m)\u001b[0m\u001b[0;34m\u001b[0m\u001b[0;34m\u001b[0m\u001b[0m\n",
      "\u001b[0;32m/usr/local/lib/python3.7/site-packages/ray/worker.py\u001b[0m in \u001b[0;36mget\u001b[0;34m(object_ids)\u001b[0m\n\u001b[1;32m   2193\u001b[0m             \u001b[0;32mif\u001b[0m \u001b[0misinstance\u001b[0m\u001b[0;34m(\u001b[0m\u001b[0mvalue\u001b[0m\u001b[0;34m,\u001b[0m \u001b[0mRayError\u001b[0m\u001b[0;34m)\u001b[0m\u001b[0;34m:\u001b[0m\u001b[0;34m\u001b[0m\u001b[0;34m\u001b[0m\u001b[0m\n\u001b[1;32m   2194\u001b[0m                 \u001b[0mlast_task_error_raise_time\u001b[0m \u001b[0;34m=\u001b[0m \u001b[0mtime\u001b[0m\u001b[0;34m.\u001b[0m\u001b[0mtime\u001b[0m\u001b[0;34m(\u001b[0m\u001b[0;34m)\u001b[0m\u001b[0;34m\u001b[0m\u001b[0;34m\u001b[0m\u001b[0m\n\u001b[0;32m-> 2195\u001b[0;31m                 \u001b[0;32mraise\u001b[0m \u001b[0mvalue\u001b[0m\u001b[0;34m\u001b[0m\u001b[0;34m\u001b[0m\u001b[0m\n\u001b[0m\u001b[1;32m   2196\u001b[0m \u001b[0;34m\u001b[0m\u001b[0m\n\u001b[1;32m   2197\u001b[0m         \u001b[0;31m# Run post processors.\u001b[0m\u001b[0;34m\u001b[0m\u001b[0;34m\u001b[0m\u001b[0;34m\u001b[0m\u001b[0m\n",
      "\u001b[0;31mRayWorkerError\u001b[0m: The worker died unexpectedly while executing this task."
     ]
    }
   ],
   "source": [
    "@ray.remote\n",
    "def f():\n",
    "    time.sleep(1)\n",
    "    return 1\n",
    "\n",
    "ray.init()\n",
    "results = ray.get([f.remote() for i in range(4)])\n",
    "ray.shutdown()"
   ]
  },
  {
   "cell_type": "code",
   "execution_count": 3,
   "metadata": {},
   "outputs": [
    {
     "ename": "NameError",
     "evalue": "name 'results' is not defined",
     "output_type": "error",
     "traceback": [
      "\u001b[0;31m---------------------------------------------------------------------------\u001b[0m",
      "\u001b[0;31mNameError\u001b[0m                                 Traceback (most recent call last)",
      "\u001b[0;32m<ipython-input-3-100f62972f2f>\u001b[0m in \u001b[0;36m<module>\u001b[0;34m\u001b[0m\n\u001b[0;32m----> 1\u001b[0;31m \u001b[0mresults\u001b[0m\u001b[0;34m\u001b[0m\u001b[0;34m\u001b[0m\u001b[0m\n\u001b[0m",
      "\u001b[0;31mNameError\u001b[0m: name 'results' is not defined"
     ]
    }
   ],
   "source": [
    "results"
   ]
  },
  {
   "cell_type": "code",
   "execution_count": 3,
   "metadata": {},
   "outputs": [],
   "source": [
    "ray.shutdown()"
   ]
  },
  {
   "cell_type": "code",
   "execution_count": null,
   "metadata": {},
   "outputs": [],
   "source": []
  }
 ],
 "metadata": {
  "kernelspec": {
   "display_name": "Python 3",
   "language": "python",
   "name": "python3"
  },
  "language_info": {
   "codemirror_mode": {
    "name": "ipython",
    "version": 3
   },
   "file_extension": ".py",
   "mimetype": "text/x-python",
   "name": "python",
   "nbconvert_exporter": "python",
   "pygments_lexer": "ipython3",
   "version": "3.7.2"
  }
 },
 "nbformat": 4,
 "nbformat_minor": 2
}
